<?xml   version="1.0"?>
<robot name="myfirst">    
    <material name="red">
        <color rgba="1 0 0 0.8" />
    </material>
    <material name="green">
        <color rgba="0 1 0 0.8" />
    </material>

    <link name="baselink">
        <visual>
            <geometry>
                <mesh filename="base.stl" />
            </geometry>
            <origin xyz="0 0 0"/>
        </visual>
        <collision>
            <origin xyz="0 0 0"/>
            <geometry>
                <mesh filename="base.stl" />
            </geometry>
        </collision>
    </link>

    <link name="link1">
        <visual>
            <geometry>
                <mesh filename="p1.stl" />
            </geometry>
            <origin xyz="0 0 1" rpy="0 0 0 " />
            <material name="green" />
        </visual>
        <collision>
            <geometry>
                <mesh filename="p1.stl" />
            </geometry>
            <origin xyz="0 0 1" rpy="0 0 0 " />
        </collision>
    </link>

    <link name="link2">
        <visual>
            <geometry>
                <mesh filename="r1.stl" />
            </geometry>
            <origin xyz="0 0 0" rpy="0 1.5708 0" />
            <material name="red" />
        </visual>
        <collision>
            <geometry>
                <mesh filename="r1.stl" />
            </geometry>
            <origin xyz="0 0 0" rpy="0 0 0" />
        </collision>
    </link>
  
    <link name="end">
        <visual>
            <geometry>
                <mesh filename="end.stl" />
            </geometry>
            <origin xyz="0 0 0" rpy="-1.5708 0 1.5708"/>
            <material name="red" />
        </visual>
        <collision>
            <geometry>
                <mesh filename="end.stl" />
            </geometry>
            <origin xyz="0 0 0" rpy="-1.5708 0 1.5708"/>
        </collision>
    </link>

    <joint name="prismatic1" type="prismatic">
        <parent link="baselink"/>
        <child link="link1"/>
        <axis xyz="0 0 1"/>
        <origin xyz="0 0 0"/>
        <limit effort="30" velocity="1.0" lower="-2.2" upper="5" />        
    </joint>

    <joint name="revolute1" type="revolute">
        <parent link="link1"/>
        <child link="link2"/>
        <axis xyz="1 0 0"/>
        <origin xyz="0 0 2" />
        <limit effort="30" velocity="1.0" lower="-2.2" upper="5" /> 
    </joint>
    <joint name="prismatic2" type="prismatic">
        <parent link="link2"/>
        <child link="end"/>
        <axis xyz="0 0 1 "/>
        <origin xyz="0 -1.5 0" rpy="1.5708 0 0"/>
        <limit effort="30" velocity="1.0" lower="-2.2" upper="5" /> 
    </joint>

    
</robot>
    